2024-04-22 14:04:48,348 ERROR: Exception on /user/susan [GET] [in /home/shield/projects/flask/flaskproj/.venv/lib/python3.8/site-packages/flask/app.py:825]
Traceback (most recent call last):
  File "/home/shield/projects/flask/flaskproj/.venv/lib/python3.8/site-packages/flask/app.py", line 1455, in wsgi_app
    response = self.full_dispatch_request()
  File "/home/shield/projects/flask/flaskproj/.venv/lib/python3.8/site-packages/flask/app.py", line 869, in full_dispatch_request
    rv = self.handle_user_exception(e)
  File "/home/shield/projects/flask/flaskproj/.venv/lib/python3.8/site-packages/flask/app.py", line 867, in full_dispatch_request
    rv = self.dispatch_request()
  File "/home/shield/projects/flask/flaskproj/.venv/lib/python3.8/site-packages/flask/app.py", line 852, in dispatch_request
    return self.ensure_sync(self.view_functions[rule.endpoint])(**view_args)
  File "/home/shield/projects/flask/flaskproj/.venv/lib/python3.8/site-packages/flask_login/utils.py", line 290, in decorated_view
    return current_app.ensure_sync(func)(*args, **kwargs)
  File "/home/shield/projects/flask/flaskproj/app/routes.py", line 82, in user
    return render_template('user.html', user=user, posts=posts)
  File "/home/shield/projects/flask/flaskproj/.venv/lib/python3.8/site-packages/flask/templating.py", line 152, in render_template
    return _render(app, template, context)
  File "/home/shield/projects/flask/flaskproj/.venv/lib/python3.8/site-packages/flask/templating.py", line 133, in _render
    rv = template.render(context)
  File "/home/shield/projects/flask/flaskproj/.venv/lib/python3.8/site-packages/jinja2/environment.py", line 1301, in render
    self.environment.handle_exception()
  File "/home/shield/projects/flask/flaskproj/.venv/lib/python3.8/site-packages/jinja2/environment.py", line 936, in handle_exception
    raise rewrite_traceback_stack(source=source)
  File "/home/shield/projects/flask/flaskproj/app/templates/user.html", line 1, in top-level template code
    {% extends "base.html" %}
  File "/home/shield/projects/flask/flaskproj/app/templates/base.html", line 32, in top-level template code
    {% block content %}{% endblock %}
  File "/home/shield/projects/flask/flaskproj/app/templates/user.html", line 19, in block 'content'
    <form action="{{ url_for('follow', username=user.username) }}" method="post">
  File "/home/shield/projects/flask/flaskproj/.venv/lib/python3.8/site-packages/flask/app.py", line 1071, in url_for
    return self.handle_url_build_error(error, endpoint, values)
  File "/home/shield/projects/flask/flaskproj/.venv/lib/python3.8/site-packages/flask/app.py", line 1060, in url_for
    rv = url_adapter.build(  # type: ignore[union-attr]
  File "/home/shield/projects/flask/flaskproj/.venv/lib/python3.8/site-packages/werkzeug/routing/map.py", line 919, in build
    raise BuildError(endpoint, values, method, self)
werkzeug.routing.exceptions.BuildError: Could not build url for endpoint 'follow' with values ['username']. Did you mean 'login' instead?
2024-04-22 14:11:28,760 INFO: Flaskapp startup [in /home/shield/projects/flask/flaskproj/app/__init__.py:51]
2024-04-22 14:11:58,650 ERROR: Exception on /edit_profile [POST] [in /home/shield/projects/flask/flaskproj/.venv/lib/python3.8/site-packages/flask/app.py:825]
Traceback (most recent call last):
  File "/home/shield/projects/flask/flaskproj/.venv/lib/python3.8/site-packages/sqlalchemy/engine/base.py", line 1969, in _exec_single_context
    self.dialect.do_execute(
  File "/home/shield/projects/flask/flaskproj/.venv/lib/python3.8/site-packages/sqlalchemy/engine/default.py", line 922, in do_execute
    cursor.execute(statement, parameters)
sqlite3.IntegrityError: UNIQUE constraint failed: user.username

The above exception was the direct cause of the following exception:

Traceback (most recent call last):
  File "/home/shield/projects/flask/flaskproj/.venv/lib/python3.8/site-packages/flask/app.py", line 1455, in wsgi_app
    response = self.full_dispatch_request()
  File "/home/shield/projects/flask/flaskproj/.venv/lib/python3.8/site-packages/flask/app.py", line 869, in full_dispatch_request
    rv = self.handle_user_exception(e)
  File "/home/shield/projects/flask/flaskproj/.venv/lib/python3.8/site-packages/flask/app.py", line 867, in full_dispatch_request
    rv = self.dispatch_request()
  File "/home/shield/projects/flask/flaskproj/.venv/lib/python3.8/site-packages/flask/app.py", line 852, in dispatch_request
    return self.ensure_sync(self.view_functions[rule.endpoint])(**view_args)
  File "/home/shield/projects/flask/flaskproj/.venv/lib/python3.8/site-packages/flask_login/utils.py", line 290, in decorated_view
    return current_app.ensure_sync(func)(*args, **kwargs)
  File "/home/shield/projects/flask/flaskproj/app/routes.py", line 97, in edit_profile
    db.session.commit()
  File "/home/shield/projects/flask/flaskproj/.venv/lib/python3.8/site-packages/sqlalchemy/orm/scoping.py", line 598, in commit
    return self._proxied.commit()
  File "/home/shield/projects/flask/flaskproj/.venv/lib/python3.8/site-packages/sqlalchemy/orm/session.py", line 1969, in commit
    trans.commit(_to_root=True)
  File "<string>", line 2, in commit
  File "/home/shield/projects/flask/flaskproj/.venv/lib/python3.8/site-packages/sqlalchemy/orm/state_changes.py", line 139, in _go
    ret_value = fn(self, *arg, **kw)
  File "/home/shield/projects/flask/flaskproj/.venv/lib/python3.8/site-packages/sqlalchemy/orm/session.py", line 1256, in commit
    self._prepare_impl()
  File "<string>", line 2, in _prepare_impl
  File "/home/shield/projects/flask/flaskproj/.venv/lib/python3.8/site-packages/sqlalchemy/orm/state_changes.py", line 139, in _go
    ret_value = fn(self, *arg, **kw)
  File "/home/shield/projects/flask/flaskproj/.venv/lib/python3.8/site-packages/sqlalchemy/orm/session.py", line 1231, in _prepare_impl
    self.session.flush()
  File "/home/shield/projects/flask/flaskproj/.venv/lib/python3.8/site-packages/sqlalchemy/orm/session.py", line 4312, in flush
    self._flush(objects)
  File "/home/shield/projects/flask/flaskproj/.venv/lib/python3.8/site-packages/sqlalchemy/orm/session.py", line 4448, in _flush
    transaction.rollback(_capture_exception=True)
  File "/home/shield/projects/flask/flaskproj/.venv/lib/python3.8/site-packages/sqlalchemy/util/langhelpers.py", line 146, in __exit__
    raise exc_value.with_traceback(exc_tb)
  File "/home/shield/projects/flask/flaskproj/.venv/lib/python3.8/site-packages/sqlalchemy/orm/session.py", line 4408, in _flush
    flush_context.execute()
  File "/home/shield/projects/flask/flaskproj/.venv/lib/python3.8/site-packages/sqlalchemy/orm/unitofwork.py", line 466, in execute
    rec.execute(self)
  File "/home/shield/projects/flask/flaskproj/.venv/lib/python3.8/site-packages/sqlalchemy/orm/unitofwork.py", line 642, in execute
    util.preloaded.orm_persistence.save_obj(
  File "/home/shield/projects/flask/flaskproj/.venv/lib/python3.8/site-packages/sqlalchemy/orm/persistence.py", line 85, in save_obj
    _emit_update_statements(
  File "/home/shield/projects/flask/flaskproj/.venv/lib/python3.8/site-packages/sqlalchemy/orm/persistence.py", line 910, in _emit_update_statements
    c = connection.execute(
  File "/home/shield/projects/flask/flaskproj/.venv/lib/python3.8/site-packages/sqlalchemy/engine/base.py", line 1416, in execute
    return meth(
  File "/home/shield/projects/flask/flaskproj/.venv/lib/python3.8/site-packages/sqlalchemy/sql/elements.py", line 517, in _execute_on_connection
    return connection._execute_clauseelement(
  File "/home/shield/projects/flask/flaskproj/.venv/lib/python3.8/site-packages/sqlalchemy/engine/base.py", line 1639, in _execute_clauseelement
    ret = self._execute_context(
  File "/home/shield/projects/flask/flaskproj/.venv/lib/python3.8/site-packages/sqlalchemy/engine/base.py", line 1848, in _execute_context
    return self._exec_single_context(
  File "/home/shield/projects/flask/flaskproj/.venv/lib/python3.8/site-packages/sqlalchemy/engine/base.py", line 1988, in _exec_single_context
    self._handle_dbapi_exception(
  File "/home/shield/projects/flask/flaskproj/.venv/lib/python3.8/site-packages/sqlalchemy/engine/base.py", line 2344, in _handle_dbapi_exception
    raise sqlalchemy_exception.with_traceback(exc_info[2]) from e
  File "/home/shield/projects/flask/flaskproj/.venv/lib/python3.8/site-packages/sqlalchemy/engine/base.py", line 1969, in _exec_single_context
    self.dialect.do_execute(
  File "/home/shield/projects/flask/flaskproj/.venv/lib/python3.8/site-packages/sqlalchemy/engine/default.py", line 922, in do_execute
    cursor.execute(statement, parameters)
sqlalchemy.exc.IntegrityError: (sqlite3.IntegrityError) UNIQUE constraint failed: user.username
[SQL: UPDATE user SET username=?, about_me=? WHERE user.id = ?]
[parameters: ('susan', '', 2)]
(Background on this error at: https://sqlalche.me/e/20/gkpj)
2024-04-27 03:16:08,863 INFO: Flaskapp startup [in /home/shield/projects/flask/flaskproj/app/__init__.py:51]
